Workbook
Name Slicer_Group1: #N/A
Name Slicer_LapCat: #N/A
Name Slicer_MalaysiaPopularity: #N/A
Name Slicer_MaleWtKg: #N/A
Name Slicer_PopularityUS2017: #N/A

Sheet Dog Breed
A1: BreedName | B1: AltBreedName | C1: Group1 | D1: Group2 | E1: MaleWtKg | F1: Temperment | G1: AvgPupPrice | H1: Intelligence | I1: Watchdog | J1: MalaysiaGuardedDog | K1: MalaysiaProhibitedDog | L1: MalaysiaPopularity | M1: PopularityUS2017 | N1: Qty Sold | O1: Average sale | P1: Affectiontae
A2: Affenpinscher | C2: Toy | D2: Companion | E2: 4 | F2: Active, Adventurous, Curious, Fun-loving, Playful, Stubborn | G2: 1000 | H2: 37 | I2: 1 | M2: 147 | N2: 300 | O2: =AVERAGEIF($A:$A, A2, $N:$N) -> 300 | P2: =IF(ISNUMBER(SEARCH("Affectionate",F1)),"With Affectionate","Without Affectionate") -> Without Affectionate
A3: Afghan Hound | C3: Sporting | D3: Sight | E3: 28 | F3: Aloof, Clownish, Dignified, Happy, Independent | G3: 2250 | H3: 79 | I3: 1 | M3: 93 | N3: 250 | O3: =AVERAGEIF($A:$A, A3, $N:$N) -> 250 | P3: =IF(ISNUMBER(SEARCH("Affectionate",F2)),"With Affectionate","Without Affectionate") -> Without Affectionate
A4: African Hunting Dog | E4: 23 | F4: Wild | N4: 500 | O4: =AVERAGEIF($A:$A, A4, $N:$N) -> 500 | P4: =IF(ISNUMBER(SEARCH("Affectionate",F3)),"With Affectionate","Without Affectionate") -> Without Affectionate
A5: Airedale Terrier | B5: Airedale | C5: Terrier | D5: Terrier | E5: 26 | F5: Alert, Confident, Courageous, Friendly, Intelligent, Outgoing | G5: 700 | H5: 29 | I5: 4 | M5: 55 | N5: 670 | O5: =AVERAGEIF($A:$A, A5, $N:$N) -> 670 | P5: =IF(ISNUMBER(SEARCH("Affectionate",F4)),"With Affectionate","Without Affectionate") -> Without Affectionate
A6: Akbash | C6: Working | D6: Guardian | E6: 53 | F6: Affectionate, Alert, Courageous, Independent, Intelligent, Loyal | G6: 600 | I6: 5 | N6: 293 | O6: =AVERAGEIF($A:$A, A6, $N:$N) -> 293 | P6: =IF(ISNUMBER(SEARCH("Affectionate",F5)),"With Affectionate","Without Affectionate") -> Without Affectionate
A7: Akita | C7: Working | D7: Herding | E7: 44 | F7: Alert, Courageous, Dignified, Docile, Friendly, Intelligent, Responsive | G7: 1000 | H7: 54 | I7: 5 | K7: 1 | M7: 47 | N7: 457 | O7: =AVERAGEIF($A:$A, A7, $N:$N) -> 457 | P7: =IF(ISNUMBER(SEARCH("Affectionate",F6)),"With Affectionate","Without Affectionate") -> With Affectionate
A8: Alaskan Malamute | B8: Malamute | C8: Working | D8: Northern | E8: 40 | F8: Affectionate, Devoted, Dignified, Friendly, Loyal, Playful | G8: 1350 | H8: 50 | I8: 5 | M8: 59 | N8: 890 | O8: =AVERAGEIF($A:$A, A8, $N:$N) -> 890 | P8: =IF(ISNUMBER(SEARCH("Affectionate",F7)),"With Affectionate","Without Affectionate") -> Without Affectionate
A9: American Bulldog | C9: Working | D9: Guardian | E9: 38 | F9: Affectionate, Alert, Courageous, Energetic, Gentle, Loving, Out-going, Social | G9: 800 | I9: 6 | K9: 1 | N9: 91 | O9: =AVERAGEIF($A:$A, A9, $N:$N) -> 91 | P9: =IF(ISNUMBER(SEARCH("Affectionate",F8)),"With Affectionate","Without Affectionate") -> With Affectionate
A10: American Eskimo Dog | C10: Non Sporting | D10: Northern | E10: 8 | F10: Alert, Energetic, Friendly, Independent, Intelligent, Protective | G10: 700 | I10: 4 | M10: 118 | N10: 25 | O10: =AVERAGEIF($A:$A, A10, $N:$N) -> 25 | P10: =IF(ISNUMBER(SEARCH("Affectionate",F9)),"With Affectionate","Without Affectionate") -> With Affectionate
A11: American Hairless Terrier | C11: Terrier | D11: Terrier | E11: 5 | F11: Alert, Lively, Loving, Intelligent, Inquisitive, Playful | G11: 400 | I11: 3 | M11: 126 | N11: 76 | O11: =AVERAGEIF($A:$A, A11, $N:$N) -> 76 | P11: =IF(ISNUMBER(SEARCH("Affectionate",F10)),"With Affectionate","Without Affectionate") -> Without Affectionate
A12: American Staffordshire Terrier | C12: Terrier | D12: Terrier | E12: 28 | F12: Attentive, Courageous, Devoted, Friendly, Loyal, Tenacious, Intelligent | G12: 900 | H12: 34 | I12: 3 | K12: 1 | M12: 83 | N12: 94 | O12: =AVERAGEIF($A:$A, A12, $N:$N) -> 94 | P12: =IF(ISNUMBER(SEARCH("Affectionate",F11)),"With Affectionate","Without Affectionate") -> Without Affectionate
A13: American Water Spaniel | C13: Sporting | D13: Gun | E13: 16 | F13: Energetic, Friendly, Intelligent, Obedient, Protective, Trainable | G13: 900 | H13: 44 | I13: 4 | M13: 167 | N13: 56 | O13: =AVERAGEIF($A:$A, A13, $N:$N) -> 56 | P13: =IF(ISNUMBER(SEARCH("Affectionate",F12)),"With Affectionate","Without Affectionate") -> Without Affectionate
A14: Anatolian Shepherd | C14: Working | D14: Guardian | E14: 52 | F14: Bold, Confident, Independent, Intelligent, Proud, Steady | G14: 800 | I14: 6 | M14: 86 | N14: 780 | O14: =AVERAGEIF($A:$A, A14, $N:$N) -> 780 | P14: =IF(ISNUMBER(SEARCH("Affectionate",F13)),"With Affectionate","Without Affectionate") -> Without Affectionate
A15: Appenzell Mountain Dog | B15: Appenzeller | C15: Working | D15: Guardian | E15: 27 | F15: Energetic, Fearless, Lively, Reliable, Self-assured, Social | G15: 700 | I15: 5 | N15: 909 | O15: =AVERAGEIF($A:$A, A15, $N:$N) -> 909 | P15: =IF(ISNUMBER(SEARCH("Affectionate",F14)),"With Affectionate","Without Affectionate") -> Without Affectionate
A16: Australian Cattle Dog/Blue Heeler | C16: Herding | D16: Herding | E16: 21 | F16: Aggressive, Alert, Energetic, Intelligent, Loyal, Protective, Responsive | G16: 600 | H16: 10 | I16: 6 | M16: 56 | N16: 101 | O16: =AVERAGEIF($A:$A, A16, $N:$N) -> 101 | P16: =IF(ISNUMBER(SEARCH("Affectionate",F15)),"With Affectionate","Without Affectionate") -> Without Affectionate
A17: Australian Kelpie | B17: Kelpie | C17: Working | D17: Herding | E17: 16 | F17: Alert, Eager, Energetic, Friendly, Intelligent, Loyal, Robust | G17: 600 | I17: 5 | N17: 102 | O17: =AVERAGEIF($A:$A, A17, $N:$N) -> 102 | P17: =IF(ISNUMBER(SEARCH("Affectionate",F16)),"With Affectionate","Without Affectionate") -> Without Affectionate
A18: Australian Shepherd | C18: Terrier | D18: Terrier | E18: 27 | F18: Active, Affectionate, Friendly, Good-natured, Intelligent, Protective, Loving | G18: 700 | H18: 42 | I18: 5 | M18: 17 | N18: 39 | O18: =AVERAGEIF($A:$A, A18, $N:$N) -> 39 | P18: =IF(ISNUMBER(SEARCH("Affectionate",F17)),"With Affectionate","Without Affectionate") -> Without Affectionate
A19: Australian Terrier | C19: Terrier | D19: Terrier | E19: 5 | F19: Alert, Compassionate, Courageous, Even Tempered, Loyal, Spirited, Intelligent | G19: 1250 | H19: 34 | I19: 3 | M19: 137 | N19: 55 | O19: =AVERAGEIF($A:$A, A19, $N:$N) -> 55 | P19: =IF(ISNUMBER(SEARCH("Affectionate",F18)),"With Affectionate","Without Affectionate") -> With Affectionate
A20: Basenji | C20: Hound | D20: Sight | E20: 11 | F20: Affectionate, Alert, Curious, Energetic, Playful, Intelligent | G20: 1100 | H20: 78 | I20: 5 | M20: 84 | N20: 49 | O20: =AVERAGEIF($A:$A, A20, $N:$N) -> 49 | P20: =IF(ISNUMBER(SEARCH("Affectionate",F19)),"With Affectionate","Without Affectionate") -> Without Affectionate
A21: Basset Hound | B21: Basset | C21: Hound | D21: Scenthound | E21: 26 | F21: Affectionate, Devoted, Friendly, Gentle, Sweet-tempered, Tenacious | G21: 400 | H21: 71 | I21: 1 | M21: 39 | N21: 76 | O21: =AVERAGEIF($A:$A, A21, $N:$N) -> 76 | P21: =IF(ISNUMBER(SEARCH("Affectionate",F20)),"With Affectionate","Without Affectionate") -> With Affectionate
A22: Beagle | C22: Hound | D22: Scenthound | E22: 11 | F22: Friendly, Gentle, Independent, Intelligent, Lively, Loving, Sweet | G22: 650 | H22: 72 | I22: 1 | M22: 6 | N22: 34 | O22: =AVERAGEIF($A:$A, A22, $N:$N) -> 34 | P22: =IF(ISNUMBER(SEARCH("Affectionate",F21)),"With Affectionate","Without Affectionate") -> With Affectionate
A23: Bearded Collie | C23: Herding | D23: Herding | E23: 23 | F23: Active, Alert, Hardy, Intelligent, Lively, Self-confident | G23: 1300 | H23: 34 | I23: 4 | M23: 125 | N23: 50 | O23: =AVERAGEIF($A:$A, A23, $N:$N) -> 50 | P23: =IF(ISNUMBER(SEARCH("Affectionate",F22)),"With Affectionate","Without Affectionate") -> Without Affectionate
A24: Beauceron | C24: Herding | D24: Herding | E24: 50 | F24: Courageous, Obedient, Loyal, Protective, Loving | G24: 1350 | I24: 5 | M24: 141 | N24: 23 | O24: =AVERAGEIF($A:$A, A24, $N:$N) -> 23 | P24: =IF(ISNUMBER(SEARCH("Affectionate",F23)),"With Affectionate","Without Affectionate") -> Without Affectionate
A25: Bedlington Terrier | C25: Terrier | D25: Terrier | E25: 9 | F25: Affectionate, Devoted, Energetic, Loyal, Playful, Reliable, Intelligent | G25: 1900 | H25: 40 | I25: 3 | M25: 151 | N25: 45 | O25: =AVERAGEIF($A:$A, A25, $N:$N) -> 45 | P25: =IF(ISNUMBER(SEARCH("Affectionate",F24)),"With Affectionate","Without Affectionate") -> Without Affectionate
A26: Belgian Shepherd Dog Sheepdog | B26: Groenendael | C26: Herding | D26: Herding | E26: 32 | F26: Active, Alert, Confident, Friendly, Hard-working, Protective, Stubborn, Watchful, Intelligent | G26: 1300 | H26: 15 | I26: 6 | M26: 120 | N26: 33 | O26: =AVERAGEIF($A:$A, A26, $N:$N) -> 33 | P26: =IF(ISNUMBER(SEARCH("Affectionate",F25)),"With Affectionate","Without Affectionate") -> With Affectionate
A27: Belgian Shepherd Laekenois | C27: Herding | D27: Herding | E27: 28 | F27: Active, Alert, Energetic, Lively, Protective, Watchful | G27: 650 | I27: 5 | N27: 53 | O27: =AVERAGEIF($A:$A, A27, $N:$N) -> 53 | P27: =IF(ISNUMBER(SEARCH("Affectionate",F26)),"With Affectionate","Without Affectionate") -> Without Affectionate
A28: Belgian Shepherd Malinois | B28: Malinois | C28: Herding | D28: Herding | E28: 27 | F28: Active, Alert, Confident, Friendly, Hard-working, Protective, Stubborn, Watchful | G28: 700 | I28: 6 | M28: 44 | N28: 87 | O28: =AVERAGEIF($A:$A, A28, $N:$N) -> 87 | P28: =IF(ISNUMBER(SEARCH("Affectionate",F27)),"With Affectionate","Without Affectionate") -> Without Affectionate
A29: Belgian Shepherd Tervuren | C29: Herding | D29: Herding | E29: 34 | F29: Alert, Attentive, Energetic, Intelligent, Loyal, Protective | G29: 1350 | H29: 14 | I29: 6 | M29: 103 | N29: 67 | O29: =AVERAGEIF($A:$A, A29, $N:$N) -> 67 | P29: =IF(ISNUMBER(SEARCH("Affectionate",F28)),"With Affectionate","Without Affectionate") -> Without Affectionate
A30: Bernese Mountain Dog | C30: Working | D30: Guardian | E30: 44 | F30: Affectionate, Faithful, Intelligent, Loyal | G30: 900 | H30: 22 | I30: 5 | M30: 25 | N30: 98 | O30: =AVERAGEIF($A:$A, A30, $N:$N) -> 98 | P30: =IF(ISNUMBER(SEARCH("Affectionate",F29)),"With Affectionate","Without Affectionate") -> Without Affectionate
A31: Bichon Frise | C31: Non Sporting | D31: Companion | E31: 4 | F31: Affectionate, Cheerful, Feisty, Gentle, Playful, Intelligent, Sensitive | G31: 850 | H31: 45 | I31: 3 | M31: 46 | N31: 104 | O31: =AVERAGEIF($A:$A, A31, $N:$N) -> 104 | P31: =IF(ISNUMBER(SEARCH("Affectionate",F30)),"With Affectionate","Without Affectionate") -> With Affectionate
A32: Black and Tan Coonhound | C32: Hound | D32: Scenthound | E32: 55 | F32: Adaptable, Easygoing, Even-tempered, Gentle, Lovable, Trusting, Intelligent | G32: 350 | H32: 44 | I32: 3 | M32: 130 | N32: 542 | O32: =AVERAGEIF($A:$A, A32, $N:$N) -> 542 | P32: =IF(ISNUMBER(SEARCH("Affectionate",F31)),"With Affectionate","Without Affectionate") -> With Affectionate
A33: Black Labrador Retriever | C33: Sporting | D33: Gun | E33: 32 | F33: Affectionate, Alert, Cheerful, Energetic, Friendly, Gentle, Intelligent, Loving, Loyal, Outgoing, Playful, Responsive, Social | G33: 1500 | H33: 7 | I33: 3 | M33: 1 | N33: 123 | O33: =AVERAGEIF($A:$A, A33, $N:$N) -> 123 | P33: =IF(ISNUMBER(SEARCH("Affectionate",F32)),"With Affectionate","Without Affectionate") -> Without Affectionate
A34: Black Mouth Cur | C34: Hound | D34: Scenthound | E34: 32 | F34: Active, Fearless, Kind, Loyal, Protective, Trainable | G34: 400 | I34: 3 | N34: 105 | O34: =AVERAGEIF($A:$A, A34, $N:$N) -> 105 | P34: =IF(ISNUMBER(SEARCH("Affectionate",F33)),"With Affectionate","Without Affectionate") -> With Affectionate
A35: Black Russian Terrier | C35: Working | D35: Guardian | E35: 51 | F35: Brave, Confident, Energetic, Hardy, Lively, Stable | G35: 2150 | I35: 6 | M35: 116 | N35: 107 | O35: =AVERAGEIF($A:$A, A35, $N:$N) -> 107 | P35: =IF(ISNUMBER(SEARCH("Affectionate",F34)),"With Affectionate","Without Affectionate") -> Without Affectionate
A36: Bloodhound | C36: Hound | D36: Scenthound | E36: 46 | F36: Affectionate, Even-tempered, Gentle, Stubborn, Independent | G36: 1000 | H36: 74 | I36: 1 | M36: 50 | N36: 891 | O36: =AVERAGEIF($A:$A, A36, $N:$N) -> 891 | P36: =IF(ISNUMBER(SEARCH("Affectionate",F35)),"With Affectionate","Without Affectionate") -> Without Affectionate
A37: Blue Lacy | C37: Sporting | D37: Gun | E37: 18 | F37: Active, Alert, Bold, Devoted, Intelligent, Intense | G37: 700 | I37: 4 | N37: 397 | O37: =AVERAGEIF($A:$A, A37, $N:$N) -> 397 | P37: =IF(ISNUMBER(SEARCH("Affectionate",F36)),"With Affectionate","Without Affectionate") -> With Affectionate
A38: Bluetick Coonhound | B38: Bluetick | C38: Hound | D38: Scenthound | E38: 28 | F38: Friendly, Active, Gentle | G38: 550 | I38: 1 | M38: 132 | N38: 675 | O38: =AVERAGEIF($A:$A, A38, $N:$N) -> 675 | P38: =IF(ISNUMBER(SEARCH("Affectionate",F37)),"With Affectionate","Without Affectionate") -> Without Affectionate
A39: Boerboel | C39: Working | D39: Guardian | E39: 80 | F39: Confident, Dominant, Intelligent, Obedient, Territorial | G39: 1750 | I39: 6 | M39: 124 | N39: 393 | O39: =AVERAGEIF($A:$A, A39, $N:$N) -> 393 | P39: =IF(ISNUMBER(SEARCH("Affectionate",F38)),"With Affectionate","Without Affectionate") -> Without Affectionate
A40: Bolognese | C40: Working | D40: Companion | E40: 3 | F40: Docile, Enterprising, Loyal, Reserved, Serious | G40: 1350 | I40: 2 | N40: 215 | O40: =AVERAGEIF($A:$A, A40, $N:$N) -> 215 | P40: =IF(ISNUMBER(SEARCH("Affectionate",F39)),"With Affectionate","Without Affectionate") -> Without Affectionate
...

Sheet summary 
A1: TOTAL COUNT OF CAT PER FUR TYPE
A2: fut type
A3: bald | B3: =COUNTIF('Cat Breed'!$D:$D, "Bald") -> 2
A4: long | B4: =COUNTIF('Cat Breed'!$D:$D, "Long") -> 20
A5: medium | B5: =COUNTIF('Cat Breed'!$D:$D, "Medium") -> 14
A6: short | B6: =COUNTIF('Cat Breed'!$D:$D, "Short") -> 30
A8: TOTAL COUNT OF DOGS PER GROUP1 CATEGORY
A9: Herding | B9: =COUNTIF('Dog Breed'!$C:C, "herding") -> 37
A10: Hound | B10: =COUNTIF('Dog Breed'!$C:C, "hound") -> 34
A11: Non sporting | B11: =COUNTIF('Dog Breed'!$C:C, "non sporting") -> 27
A12: southern | B12: =COUNTIF('Dog Breed'!$C:C, "southern") -> 1
A13: sporting | B13: =COUNTIF('Dog Breed'!$C:C, "sporting") -> 40
A14: terrier | B14: =COUNTIF('Dog Breed'!$C:C, "terrier") -> 36
A15: toy | B15: =COUNTIF('Dog Breed'!$C:C, "toy") -> 21
A16: working | B16: =COUNTIF('Dog Breed'!$C:C, "working") -> 49
A18: TOP 10 CAT BREEDS BASED ON POPULARITY | J18: AVERAGE PRICE
A19: {=_xlfn.TAKE(_xlfn._xlws.SORT(_xlfn._xlws.FILTER('[1]Dataset-cat_breed_characteristi'!A:I, '[1]Dataset-cat_breed_characteristi'!I:I<>""), 9,1),10)} -> Exotic Shorthair | B19: 0 | C19: Lap | D19: Short | E19: 5 | F19: Affectionate, Sweet, Loyal, Quiet, Peaceful | G19: 1750 | H19: 2 | I19: 1 | J19: =ROUND(AVERAGE(G19:G28), 2) -> 1270
A20: Persian | B20: 0 | C20: Lap | D20: Long | E20: 6 | F20: Affectionate, Loyal, Sedate, Quiet | G20: 1250 | H20: 3 | I20: 2 | J20: =ROUND(AVERAGE(G20:G29), 2) -> 1216.67
A21: Maine Coon | B21: 0 | C21: Lap | D21: Long | E21: 7 | F21: Adaptable, Intelligent, Loving, Gentle, Independent | G21: 1600 | H21: 1 | I21: 3 | J21: =ROUND(AVERAGE(G21:G30), 2) -> 1212.5
A22: Ragdoll | B22: 0 | C22: Lap | D22: Long | E22: 7 | F22: Affectioante, Friendly, Gentle, Quiet, Easygoing | G22: 1000 | H22: 7 | I22: 4 | J22: =ROUND(AVERAGE(G22:G31), 2) -> 1157.14
A23: British Shorthair | B23: 0 | C23: Lap | D23: Short | E23: 7 | F23: Affectionate, Easygoing, Gentle, Loyal, Patient, Calm | G23: 1750 | H23: 6 | I23: 5 | J23: =ROUND(AVERAGE(G23:G32), 2) -> 1157.14
A24: American Shorthair | B24: 0 | C24: Lap | D24: Short | E24: 6 | F24: Active, Curious, Easygoing, Playful, Calm | G24: 900 | H24: 5 | I24: 6 | J24: =ROUND(AVERAGE(G24:G33), 2) -> 992.86
A25: Abyssinian | B25: 0 | C25: Lap | D25: Short | E25: 4 | F25: Active, Energetic, Independent, Intelligent, Gentle | G25: 1050 | H25: 0 | I25: 7 | J25: =ROUND(AVERAGE(G25:G34), 2) -> 935.71
A26: Canadian Hairless | B26: 0 | C26: Lap | D26: Bald | E26: 5 | F26: Loyal, Inquisitive, Friendly, Quiet, Gentle | G26: 1450 | H26: 0 | I26: 8 | J26: =ROUND(AVERAGE(G26:G35), 2) -> 871.43
A27: Sphynx (hairless cat) | B27: Sphynx | C27: Lap | D27: Bald | E27: 5 | F27: Loyal, Inquisitive, Friendly, Quiet, Gentle | G27: 1450 | H27: 0 | I27: 8 | J27: =ROUND(AVERAGE(G27:G36), 2) -> 735.71
A28: Siamese | B28: 0 | C28: Lap | D28: Short | E28: 6 | F28: Active, Agile, Clever, Sociable, Loving, Energetic | G28: 500 | H28: 0 | I28: 9 | J28: =ROUND(AVERAGE(G28:G37), 2) -> 642.86
A30: Buttom 10 CATS BREEDS ON POPULARITY
A31: {=_xlfn.TAKE(_xlfn._xlws.SORT(_xlfn._xlws.FILTER('[1]Dataset-cat_breed_characteristi'!A:I, '[1]Dataset-cat_breed_characteristi'!I:I<>""), 9,-1),10)} -> BreedName | B31: AltBreedName | C31: LapCat | D31: Fur | E31: MaleWtKg | F31: Temperment | G31: AvgKittenPrice | H31: MalaysiaPopularity | I31: PopularityUS2017 | J31: Avearge price
A32: American Wirehair | B32: 0 | C32: Lap | D32: Medium | E32: 6 | F32: Affectionate, Curious, Gentle, Intelligent, Interactive, Lively, Loyal, Playful, Sensible, Social | G32: 1000 | H32: 0 | I32: 41 | J32: =ROUND(AVERAGE(G32:G40), 2) -> 711.11
A33: Korat | B33: 0 | C33: Lap | D33: Long | E33: 4 | F33: Affectionate, Friendly, Gentle, Intelligent, Playful, Quiet | G33: 600 | H33: 0 | I33: 40 | J33: =ROUND(AVERAGE(G33:G41), 2) -> 675
A34: LaPerm | B34: 0 | C34: Lap | D34: Long | E34: 4 | F34: Intelligent, Clever, Active, Genlte | G34: 500 | H34: 0 | I34: 39 | J34: =ROUND(AVERAGE(G34:G42), 2) -> 685.71
A35: Burmilla | B35: 0 | C35: Lap | D35: Long | E35: 5 | F35: Easygoing, Friendly, Intelligent, Lively, Playful, Social | G35: 600 | H35: 0 | I35: 38 | J35: =ROUND(AVERAGE(G35:G43), 2) -> 828.57
A36: Turkish Van | B36: 0 | C36: Non Lap | D36: Long | E36: 6 | F36: Agile, Intelligent, Loyal, Playful, Energetic | G36: 500 | H36: 0 | I36: 37 | J36: =ROUND(AVERAGE(G36:G44), 2) -> 957.14
A37: Bobtail | B37: 0 | C37: Lap | D37: Medium | E37: 6 | F37: Intelligent, Interactive, Lively, Playful, Sensitive | G37: 800 | H37: 0 | I37: 36 | J37: =ROUND(AVERAGE(G37:G45), 2) -> 1100
A38: Havana | B38: 0 | C38: Lap | D38: Medium | E38: 4 | F38: Affectionate, Curious, Demanding, Friendly, Intelligent, Playful | G38: 900 | H38: 0 | I38: 35 | J38: =ROUND(AVERAGE(G38:G46), 2) -> 1200
A39: Bombay | B39: 0 | C39: Lap | D39: Short | E39: 4 | F39: Affectionate, Dependent, Gentle, Intelligent, Playful | G39: 500 | H39: 0 | I39: 34 | J39: =ROUND(AVERAGE(G39:G47), 2) -> 1271.43
A40: Ragamuffin | B40: 0 | C40: Lap | D40: Medium | E40: 7 | F40: Affectionate, Friendly, Gentle, Calm | G40: 1000 | H40: 0 | I40: 32 | J40: =ROUND(AVERAGE(G40:G48), 2) -> 1400
A42: Top 10 DOGS BREEDS BASED ON POPULARITY | N42: Average price
A43: {=_xlfn.TAKE(_xlfn._xlws.SORT(_xlfn._xlws.FILTER('[2]Dataset-dog_breed_characteristi'!A:M, '[2]Dataset-dog_breed_characteristi'!M:M<>""), 13,1),10)} -> Black Labrador Retriever | B43: 0 | C43: Sporting | D43: Gun | E43: 32 | F43: Affectionate, Alert, Cheerful, Energetic, Friendly, Gentle, Intelligent, Loving, Loyal, Outgoing, Playful, Responsive, Social | G43: 1500 | H43: 7 | I43: 3 | J43: 0 | K43: 0 | L43: 0 | M43: 1 | N43: =ROUND(AVERAGE(G43:G52), 2) -> 1620
A44: Chocolate Labrador Retriever | B44: 0 | C44: Sporting | D44: Gun | E44: 32 | F44: Affectionate, Alert, Cheerful, Energetic, Friendly, Gentle, Intelligent, Loving, Loyal, Outgoing, Playful, Responsive, Social | G44: 1500 | H44: 7 | I44: 3 | J44: 0 | K44: 0 | L44: 0 | M44: 1 | N44: =ROUND(AVERAGE(G44:G53), 2) -> 1633.33
...

Sheet task 2
A3: Row Labels | B3: Count of BreedName
A4: Bald | B4: 2
A5: Long | B5: 20 | D5: Row Labels | E5: Count of BreedName
A6: Medium | B6: 14 | D6: With Affectionate | E6: 26
A7: Short | B7: 30 | D7: Without Affectionate | E7: 41
A8: (blank) | B8: 1 | D8: Grand Total | E8: 67
A9: Grand Total | B9: 67
A12: Row Labels | B12: Count of BreedName | D12: Row Labels | E12: Count of BreedName
A13: Companion | B13: 35 | D13: With Affectionate | E13: 71
A14: Guardian | B14: 34 | D14: Without Affectionate | E14: 179
A15: Gun | B15: 40 | D15: Grand Total | E15: 250
A16: Gun Dogs | B16: 1
A17: Herding | B17: 36
A18: Northern | B18: 23
A19: Scenthound | B19: 19
A20: Sight | B20: 19
A21: Southern | B21: 1
A22: Terrier | B22: 38
A23: (blank) | B23: 4
A24: Grand Total | B24: 250

Sheet Cat Breed
A1: BreedName | B1: AltBreedName | C1: LapCat | D1: Fur | E1: MaleWtKg | F1: Temperment | G1: AvgKittenPrice | H1: MalaysiaPopularity | I1: PopularityUS2017 | J1: Qty Sold | K1: Average sales | L1: affectionate | M1: Column1
A2: Abyssinian | C2: Lap | D2: Short | E2: 4 | F2: Active, Energetic, Independent, Intelligent, Gentle | G2: 1050 | I2: 7 | J2: 79 | K2: =AVERAGEIF($A:$A, A2, $J:$J) -> 79 | L2: =IF(ISNUMBER(SEARCH("Affectionate",F1)),"With Affectionate","Without Affectionate") -> Without Affectionate
A3: American Curl | C3: Lap | D3: Medium | E3: 4 | F3: Affectionate, Curious, Intelligent, Interactive, Lively, Playful, Social | G3: 1400 | I3: 26 | J3: 93 | K3: =AVERAGEIF($A:$A, A3, $J:$J) -> 93 | L3: =IF(ISNUMBER(SEARCH("Affectionate",F2)),"With Affectionate","Without Affectionate") -> Without Affectionate
A4: American Shorthair | C4: Lap | D4: Short | E4: 6 | F4: Active, Curious, Easygoing, Playful, Calm | G4: 900 | H4: 5 | I4: 6 | J4: 121 | K4: =AVERAGEIF($A:$A, A4, $J:$J) -> 121 | L4: =IF(ISNUMBER(SEARCH("Affectionate",F3)),"With Affectionate","Without Affectionate") -> With Affectionate
A5: American Wirehair | C5: Lap | D5: Medium | E5: 6 | F5: Affectionate, Curious, Gentle, Intelligent, Interactive, Lively, Loyal, Playful, Sensible, Social | G5: 1000 | I5: 41 | J5: 11 | K5: =AVERAGEIF($A:$A, A5, $J:$J) -> 11 | L5: =IF(ISNUMBER(SEARCH("Affectionate",F4)),"With Affectionate","Without Affectionate") -> Without Affectionate
A6: Applehead Siamese | C6: Lap | D6: Short | E6: 6 | F6: Active, Agile, Clever, Sociable, Loving, Energetic | G6: 1600 | J6: 15 | K6: =AVERAGEIF($A:$A, A6, $J:$J) -> 15 | L6: =IF(ISNUMBER(SEARCH("Affectionate",F5)),"With Affectionate","Without Affectionate") -> With Affectionate
A7: Balinese | C7: Non Lap | D7: Long | E7: 4 | F7: Affectionate, Intelligent, Playful | G7: 1300 | I7: 31 | J7: 5 | K7: =AVERAGEIF($A:$A, A7, $J:$J) -> 5 | L7: =IF(ISNUMBER(SEARCH("Affectionate",F6)),"With Affectionate","Without Affectionate") -> Without Affectionate
A8: Bengal | C8: Non Lap | D8: Medium | E8: 6 | F8: Active, Agile, Lively, Affectionate, Energetic, Rambunctious | G8: 1250 | H8: 8 | J8: 10 | K8: =AVERAGEIF($A:$A, A8, $J:$J) -> 10 | L8: =IF(ISNUMBER(SEARCH("Affectionate",F7)),"With Affectionate","Without Affectionate") -> With Affectionate
A9: Birman | C9: Lap | D9: Long | E9: 5 | F9: Affectionate, Active, Gentle, Social | G9: 850 | I9: 15 | J9: 93 | K9: =AVERAGEIF($A:$A, A9, $J:$J) -> 93 | L9: =IF(ISNUMBER(SEARCH("Affectionate",F8)),"With Affectionate","Without Affectionate") -> With Affectionate
A10: Bobtail | C10: Lap | D10: Medium | E10: 6 | F10: Intelligent, Interactive, Lively, Playful, Sensitive | G10: 800 | I10: 36 | J10: 45 | K10: =AVERAGEIF($A:$A, A10, $J:$J) -> 45 | L10: =IF(ISNUMBER(SEARCH("Affectionate",F9)),"With Affectionate","Without Affectionate") -> With Affectionate
A11: Bombay | C11: Lap | D11: Short | E11: 4 | F11: Affectionate, Dependent, Gentle, Intelligent, Playful | G11: 500 | I11: 34 | J11: 29 | K11: =AVERAGEIF($A:$A, A11, $J:$J) -> 29 | L11: =IF(ISNUMBER(SEARCH("Affectionate",F10)),"With Affectionate","Without Affectionate") -> Without Affectionate
A12: British Shorthair | C12: Lap | D12: Short | E12: 7 | F12: Affectionate, Easygoing, Gentle, Loyal, Patient, Calm | G12: 1750 | H12: 6 | I12: 5 | J12: 26 | K12: =AVERAGEIF($A:$A, A12, $J:$J) -> 26 | L12: =IF(ISNUMBER(SEARCH("Affectionate",F11)),"With Affectionate","Without Affectionate") -> With Affectionate
A13: Burmese | C13: Lap | D13: Short | E13: 5 | F13: Curious, Intelligent, Gentle, Social, Interactive, Playful, Lively | G13: 1250 | H13: 4 | I13: 16 | J13: 77 | K13: =AVERAGEIF($A:$A, A13, $J:$J) -> 77 | L13: =IF(ISNUMBER(SEARCH("Affectionate",F12)),"With Affectionate","Without Affectionate") -> With Affectionate
A14: Burmilla | C14: Lap | D14: Long | E14: 5 | F14: Easygoing, Friendly, Intelligent, Lively, Playful, Social | G14: 600 | I14: 38 | J14: 55 | K14: =AVERAGEIF($A:$A, A14, $J:$J) -> 55 | L14: =IF(ISNUMBER(SEARCH("Affectionate",F13)),"With Affectionate","Without Affectionate") -> Without Affectionate
A15: Calico | C15: Generic | D15: Short | E15: 6 | F15: Active, Curious, Easygoing, Playful, Calm | G15: 100 | J15: 54 | K15: =AVERAGEIF($A:$A, A15, $J:$J) -> 54 | L15: =IF(ISNUMBER(SEARCH("Affectionate",F14)),"With Affectionate","Without Affectionate") -> Without Affectionate
A16: Canadian Hairless | C16: Lap | D16: Bald | E16: 5 | F16: Loyal, Inquisitive, Friendly, Quiet, Gentle | G16: 1450 | I16: 8 | J16: 35 | K16: =AVERAGEIF($A:$A, A16, $J:$J) -> 35 | L16: =IF(ISNUMBER(SEARCH("Affectionate",F15)),"With Affectionate","Without Affectionate") -> Without Affectionate
A17: Chartreux | C17: Lap | D17: Short | E17: 6 | F17: Affectionate, Loyal, Intelligent, Social, Lively, Playful | G17: 1250 | I17: 27 | J17: 47 | K17: =AVERAGEIF($A:$A, A17, $J:$J) -> 47 | L17: =IF(ISNUMBER(SEARCH("Affectionate",F16)),"With Affectionate","Without Affectionate") -> Without Affectionate
A18: Chausie | C18: Non Lap | D18: Short | E18: 5 | F18: Affectionate, Intelligent, Playful, Social | G18: 1500 | J18: 84 | K18: =AVERAGEIF($A:$A, A18, $J:$J) -> 84 | L18: =IF(ISNUMBER(SEARCH("Affectionate",F17)),"With Affectionate","Without Affectionate") -> With Affectionate
A19: Chinchilla | C19: Rodent | D19: Short | E19: 1 | F19: Active, Playful | G19: 200 | J19: 93 | K19: =AVERAGEIF($A:$A, A19, $J:$J) -> 93 | L19: =IF(ISNUMBER(SEARCH("Affectionate",F18)),"With Affectionate","Without Affectionate") -> With Affectionate
A20: Cornish Rex | C20: Lap | D20: Short | E20: 3 | F20: Affectionate, Intelligent, Active, Curious, Playful | G20: 1000 | I20: 11 | J20: 101 | K20: =AVERAGEIF($A:$A, A20, $J:$J) -> 101 | L20: =IF(ISNUMBER(SEARCH("Affectionate",F19)),"With Affectionate","Without Affectionate") -> Without Affectionate
A21: Cymric | C21: Lap | D21: Long | E21: 5 | F21: Gentle, Loyal, Intelligent, Playful | G21: 400 | J21: 125 | K21: =AVERAGEIF($A:$A, A21, $J:$J) -> 125 | L21: =IF(ISNUMBER(SEARCH("Affectionate",F20)),"With Affectionate","Without Affectionate") -> With Affectionate
A22: Devon Rex | C22: Lap | D22: Short | E22: 3 | F22: Intelligent, Active, Mischevious, Playful | G22: 800 | I22: 12 | J22: 115 | K22: =AVERAGEIF($A:$A, A22, $J:$J) -> 115 | L22: =IF(ISNUMBER(SEARCH("Affectionate",F21)),"With Affectionate","Without Affectionate") -> Without Affectionate
A23: Dilute Calico | C23: Generic | D23: Short | E23: 6 | F23: Active, Curious, Easygoing, Playful, Calm | G23: 100 | J23: 154 | K23: =AVERAGEIF($A:$A, A23, $J:$J) -> 154 | L23: =IF(ISNUMBER(SEARCH("Affectionate",F22)),"With Affectionate","Without Affectionate") -> Without Affectionate
A24: Dilute Tortoiseshell | C24: Generic | D24: Short | E24: 6 | F24: Active, Curious, Easygoing, Playful, Calm | G24: 100 | J24: 198 | K24: =AVERAGEIF($A:$A, A24, $J:$J) -> 198 | L24: =IF(ISNUMBER(SEARCH("Affectionate",F23)),"With Affectionate","Without Affectionate") -> Without Affectionate
A25: Domestic Long Hair | C25: Generic | D25: Long | E25: 6 | F25: Active, Curious, Easygoing, Playful, Calm | G25: 100 | J25: 76 | K25: =AVERAGEIF($A:$A, A25, $J:$J) -> 76 | L25: =IF(ISNUMBER(SEARCH("Affectionate",F24)),"With Affectionate","Without Affectionate") -> Without Affectionate
A26: Domestic Medium Hair | C26: Generic | D26: Medium | E26: 6 | F26: Active, Curious, Easygoing, Playful, Calm | G26: 100 | J26: 95 | K26: =AVERAGEIF($A:$A, A26, $J:$J) -> 95 | L26: =IF(ISNUMBER(SEARCH("Affectionate",F25)),"With Affectionate","Without Affectionate") -> Without Affectionate
A27: Domestic Short Hair | C27: Generic | D27: Short | E27: 6 | F27: Active, Curious, Easygoing, Playful, Calm | G27: 100 | J27: 39 | K27: =AVERAGEIF($A:$A, A27, $J:$J) -> 39 | L27: =IF(ISNUMBER(SEARCH("Affectionate",F26)),"With Affectionate","Without Affectionate") -> Without Affectionate
A28: Egyptian Mau | C28: Lap | D28: Medium | E28: 5 | F28: Agile, Dependent, Gentle, Intelligent, Lively, Loyal, Playful | G28: 800 | I28: 20 | J28: 45 | K28: =AVERAGEIF($A:$A, A28, $J:$J) -> 45 | L28: =IF(ISNUMBER(SEARCH("Affectionate",F27)),"With Affectionate","Without Affectionate") -> Without Affectionate
A29: Exotic Shorthair | C29: Lap | D29: Short | E29: 5 | F29: Affectionate, Sweet, Loyal, Quiet, Peaceful | G29: 1750 | H29: 2 | I29: 1 | J29: 54 | K29: =AVERAGEIF($A:$A, A29, $J:$J) -> 54 | L29: =IF(ISNUMBER(SEARCH("Affectionate",F28)),"With Affectionate","Without Affectionate") -> Without Affectionate
A30: Extra-Toes Cat (Hemingway Polydactyl) | C30: Lap | D30: Medium | E30: 5 | F30: Six-Toed | G30: 2000 | J30: 67 | K30: =AVERAGEIF($A:$A, A30, $J:$J) -> 67 | L30: =IF(ISNUMBER(SEARCH("Affectionate",F29)),"With Affectionate","Without Affectionate") -> With Affectionate
A31: Havana | C31: Lap | D31: Medium | E31: 4 | F31: Affectionate, Curious, Demanding, Friendly, Intelligent, Playful | G31: 900 | I31: 35 | J31: 71 | K31: =AVERAGEIF($A:$A, A31, $J:$J) -> 71 | L31: =IF(ISNUMBER(SEARCH("Affectionate",F30)),"With Affectionate","Without Affectionate") -> Without Affectionate
A32: Himalayan | C32: Lap | D32: Long | E32: 6 | F32: Dependent, Gentle, Intelligent, Quiet, Social | G32: 800 | J32: 72 | K32: =AVERAGEIF($A:$A, A32, $J:$J) -> 72 | L32: =IF(ISNUMBER(SEARCH("Affectionate",F31)),"With Affectionate","Without Affectionate") -> With Affectionate
A33: Japanese Bobtail | C33: Lap | D33: Long | E33: 4 | F33: Active, Agile, Clever, Easygoing, Intelligent, Lively, Loyal, Playful, Social | G33: 800 | I33: 24 | J33: 43 | K33: =AVERAGEIF($A:$A, A33, $J:$J) -> 43 | L33: =IF(ISNUMBER(SEARCH("Affectionate",F32)),"With Affectionate","Without Affectionate") -> Without Affectionate
A34: Javanese | C34: Non Lap | D34: Medium | E34: 4 | F34: Active, Devoted, Intelligent, Playful | G34: 1200 | J34: 57 | K34: =AVERAGEIF($A:$A, A34, $J:$J) -> 57 | L34: =IF(ISNUMBER(SEARCH("Affectionate",F33)),"With Affectionate","Without Affectionate") -> Without Affectionate
A35: Korat | C35: Lap | D35: Long | E35: 4 | F35: Affectionate, Friendly, Gentle, Intelligent, Playful, Quiet | G35: 600 | I35: 40 | J35: 78 | K35: =AVERAGEIF($A:$A, A35, $J:$J) -> 78 | L35: =IF(ISNUMBER(SEARCH("Affectionate",F34)),"With Affectionate","Without Affectionate") -> Without Affectionate
A36: LaPerm | C36: Lap | D36: Long | E36: 4 | F36: Intelligent, Clever, Active, Genlte | G36: 500 | I36: 39 | J36: 89 | K36: =AVERAGEIF($A:$A, A36, $J:$J) -> 89 | L36: =IF(ISNUMBER(SEARCH("Affectionate",F35)),"With Affectionate","Without Affectionate") -> With Affectionate
A37: Maine Coon | C37: Lap | D37: Long | E37: 7 | F37: Adaptable, Intelligent, Loving, Gentle, Independent | G37: 1600 | H37: 1 | I37: 3 | J37: 99 | K37: =AVERAGEIF($A:$A, A37, $J:$J) -> 99 | L37: =IF(ISNUMBER(SEARCH("Affectionate",F36)),"With Affectionate","Without Affectionate") -> Without Affectionate
A38: Manx | C38: Lap | D38: Short | E38: 5 | F38: Easygoing, Intelligent, Loyal, Playful, Social | G38: 500 | I38: 23 | J38: 110 | K38: =AVERAGEIF($A:$A, A38, $J:$J) -> 110 | L38: =IF(ISNUMBER(SEARCH("Affectionate",F37)),"With Affectionate","Without Affectionate") -> Without Affectionate
A39: Munchkin | C39: Lap | D39: Medium | E39: 3 | F39: Agile, Easygoing, Intelligent, Playful | G39: 1500 | J39: 155 | K39: =AVERAGEIF($A:$A, A39, $J:$J) -> 155 | L39: =IF(ISNUMBER(SEARCH("Affectionate",F38)),"With Affectionate","Without Affectionate") -> Without Affectionate
A40: Nebelung | C40: Lap | D40: Long | E40: 4 | F40: Gentle, Quiet, Shy, Playful | G40: 500 | J40: 45 | K40: =AVERAGEIF($A:$A, A40, $J:$J) -> 45 | L40: =IF(ISNUMBER(SEARCH("Affectionate",F39)),"With Affectionate","Without Affectionate") -> Without Affectionate
...
